Workbook

Sheet CASHFLOW BUDGET 3
A2: Income | B2: Actual from Last Period | C2: Budget For Next Period | E2: EXPENSES | F2: Actual from Last Period | G2: Budget For Next Period | I2: Actual from Last Period | J2: Budget For Next Period
A4: Active Income | E4: NON-DISCRETIONARY EXPENSES | H4: DISCRETIONARY EXPENSES
A5: Salary | B5: 934324 | E5: FOOD | H5: Food
A6: Freelancing (Corporate Writings) | B6: 200000 | E6: Groceries | F6: 80000 | H6: Dinning Out
A7: Gross Active Income | B7: =B5+B6 -> 1134324 | E7: Eating Out | F7: 0 | H7: Casual eating | I7: 20000
E8: Total | F8: =SUM(F6:F7) -> 80000 | H8: Total | I8: =SUM(I6:I7) -> 20000
A9: Federal Income Tax | B9: 0
A10: State Income Tax | B10: 151815.14
A11: Housing | B11: 4680.95 | E11: Toileteries & Essentials | H11: Subscriptions
A12: Pension | B12: 27827.91 | E12: Toileteries | F12: 5000 | H12: Cable
A13: Health Insurance | E13: Total | F13: =F12 -> 5000 | H13: Club & Gym Membership
A14: Other | B14: 0 | H14: WiFi
A15: Total Deductions | B15: =SUM(B9:B14) -> 184324 | E15: Housing | H15: Other Subscriptions | I15: 15000
A16: Net Active Income | B16: =B7-B15 -> 950000 | E16: Rent/Mortgage | F16: 41666.667 | H16: Total Subscriptions | I16: =SUM(I12:I15) -> 15000
E17: Power Supply | F17: 3000
A18: Passive Income | E18: Water | F18: =1000*3 -> 3000 | H18: Shopping
A19: Dividends | B19: 0 | E19: Waste | F19: 1000 | H19: Chlothing/Jewlery | I19: 50000
A20: Rent | B20: 0 | E20: State Taxes | F20: 0 | H20: Households | I20: 20000
A21: Annuities | B21: 0 | E21: Federal Taxes | F21: 0 | H21: Total Shopping | I21: =SUM(I19:I20) -> 70000
A22: Other Income | B22: 0 | E22: Household staff salaries | F22: 25000
A23: Gross Passive Income | B23: =B19+B20+B21+B22 -> 0 | E23: Total | F23: =SUM(F16:F22) -> 73666.667
H24: Entertainment
A25: Net Income | B25: =B16+B23 -> 950000 | E25: Education | H25: Movie, Concerts social events
E26: Children School Fees | H26: Holidays and travels
A27: PAY YOURSELF FIRST | B27: % of Net Income | E27: Tuition | H27: Total | I27: =SUM(I25:I26) -> 0
A28: TOTAL TX TO INVESTMENT | C28: =C34+C32+C31+C30+C29 -> 190000 | E28: Total Education | F28: =SUM(F26:F27) -> 0
A29: TX TO EMERGENCY FUND | B29: 5 | C29: =B29%*B25 -> 47500 | H29: Gifts and Charity
A30: TX TO EXTRA RETIRNMENT SAVINGS | B30: 5 | C30: =B30%*B25 -> 47500 | E30: Transportation | H30: Gifts
A31: TX TO COLLEGE FUND | B31: 0 | C31: =B31%*B25 -> 0 | E31: Auto Fuel | H31: Charity | I31: 30000
A32: TX TO MORTGAGE | B32: 0 | C32: =B32%*B25 -> 0 | E32: Auto Maintainance | H32: Sponsorships | I32: 10000
A33: TX TO PAY INTEREST | B33: 0 | C33: =B33%*B25 -> 0 | E33: Auto Licenses & Taxes | H33: Total | I33: =SUM(I30:I32) -> 40000
A34: TX TO INVESTMENT | B34: 10 | C34: =B34%*B25 -> 95000 | E34: Auto Insurance
A35: Total PYF | C35: =C34+C33+C32+C31+C30+C29 -> 190000 | E35: Taxi | F35: 60000
E36: Total Transporation | F36: =SUM(F31:F35) -> 60000
E38: Interest Cost
E39: Commerical Loans Reayments | F39: 100000
E40: Staff Loans repayments
E41: Credit cards Repayments
E42: Other Interest payments
E43: Total Interest | F43: =SUM(F39:F42) -> 100000
...

Sheet Cashflow balance sheet 4
B4: Income Generating Assets | C4: Open Bal | D4: Intrest earned | E4: tenor | F4: closing bal | H4: Intrest Bearing Liabilities | I4: Open Bal | J4: Intrest paid | K4: tenor | L4: closing bal
B5: Savings & Checking | C5: 10000 | D5: 0 | E5: 0 | F5: =SUM(C5:E5) -> 10000 | H5: Asset Financing | I5: 1 | J5: 0 | K5: 0 | L5: =SUM(I5:K5) -> 1
B6: Fixed Deposits | C6: 0 | D6: 0 | E6: 0 | F6: =SUM(C6:E6) -> 0 | H6: Student Loans | I6: 0 | J6: 0 | K6: 0 | L6: =SUM(I6:K6) -> 0
B7: Private Bonds | C7: 0 | D7: 0 | E7: 0 | F7: =SUM(C7:E7) -> 0 | H7: Mortgage | I7: 0 | J7: 0 | K7: 0 | L7: =SUM(I7:K7) -> 0
B8: Govt Bonds | C8: 0 | D8: 0 | E8: 0 | F8: =SUM(C8:E8) -> 0 | H8: Personal Loans | I8: 0 | J8: 0 | K8: 0 | L8: =SUM(I8:K8) -> 0
B9: Equity | C9: 0 | D9: 0 | E9: 0 | F9: =SUM(C9:E9) -> 0 | H9: Credit Card | I9: 0 | J9: 0 | K9: 0 | L9: =SUM(I9:K9) -> 0
B10: REITS | C10: 0 | D10: 0 | E10: 0 | F10: =SUM(C10:E10) -> 0 | H10: Retirnment | I10: 0 | J10: 0 | K10: 0 | L10: =SUM(I10:K10) -> 0
B11: Mutual Funds | C11: 0 | D11: 0 | E11: 0 | F11: =SUM(C11:E11) -> 0 | H11: College Fund | I11: 0 | J11: 0 | K11: 0 | L11: =SUM(I11:K11) -> 0
B12: Property | C12: 0 | D12: 0 | E12: 0 | F12: =SUM(C12:E12) -> 0 | H12: Target Savings Funds | I12: 0 | J12: 0 | K12: 0 | L12: =SUM(I12:K12) -> 0
B13: Retirnment Accounts | C13: 707863.29 | D13: 102280.63 | E13: 0 | F13: =SUM(C13:E13) -> 810143.92 | I13: 0 | K13: 0 | L13: =SUM(I13:K13) -> 0
B14: Profit Share | C14: 0 | D14: 0 | E14: 0 | F14: =SUM(C14:E14) -> 0 | L14: =SUM(I14:K14) -> 0
B15: Total Income Generating Asset | C15: =SUM(C5:C14) -> 717863.29 | D15: =SUM(D5:D14) -> 102280.63 | E15: =SUM(E5:E14) -> 0 | F15: =C15+D15+E15 -> 820143.92 | H15: Total Interest Generating Liability | I15: =SUM(I5:I14) -> 1 | J15: =SUM(J5:J14) -> 0 | K15: =SUM(K5:K14) -> 0 | L15: =I15+J15+K15 -> 1
B17: Non-Income Generating Assets | H17: Non-Intreat Generating Liabilities
B18: Cash | C18: 10000 | E18: 0 | H18: Personal Loans | I18: 285100 | K18: 0
B19: Crypto Curencies | C19: 0 | E19: 0 | H19: Company drawings | I19: 0 | K19: 0
B20: Zero dividend Securities | C20: 800000 | E20: 0 | H20: Government Taxes | I20: 0 | K20: 0
B21: Land & Property | C21: 0 | E21: 0 | H21: Accrued Wages | I21: 0 | K21: 0
B22: Art | C22: 0 | E22: 0 | I22: 0 | K22: 0
B23: Patents | C23: 0 | E23: 0
B24: Furniture/ Fixtures | C24: 710000 | E24: 0
B25: Others | C25: 2000000 | E25: 0
B26: Total Non-Income Generating Asset | C26: =SUM(C18:C25) -> 3520000 | D26: =SUM(D18:D25) -> 0 | E26: =SUM(E18:E25) -> 0 | F26: =C26+D26+E26 -> 3520000 | H26: Total Non-Interest Generating Liability | I26: =SUM(I18:I25) -> 285100 | J26: =SUM(J18:J25) -> 0 | K26: =SUM(K18:K25) -> 0 | L26: =I26+J26+K26 -> 285100
B28: Total Assets | C28: =F15+F26 -> 4340143.9
B29: Total Liabilities | C29: =L15+L26 -> 285101
B30: Coverage Ratio | C30: =C28/C29 -> 15.22318
B31: Cash Ratio | C31: =D15/L15 -> 102280.63

Sheet goals sheet 1
A2: Financial Events Calculator
A4: Age | B4: 26
A6: Desired Retirnment Age | B6: 65
A8: Period to Retire | B8: =B6-B4 -> 39 | D8: =B8*12 -> 468 | E8: number of paychecks
A11: Financial Goals
A13: Financial Goal | C13: Savings (PV) | D13: Intrest Rate (i) | E13: Periods | F13: Cost of my Goal
A14: Retirnment | C14: 69999 | D14: 0.05 | E14: 6
A16: Mortagage
A18: College Fund
A20: Emergency Fund
A22: New Goal
A24: New Goal
A26: New Goal

Sheet Personal Cashflow5
A1: Inflow | D1: Outflow
A3: Active Income | B3: ='CASHFLOW BUDGET 3'!B16 -> 950000 | D3: Operations | E3: ='CASHFLOW BUDGET 3'!F66 -> 558666.67 | F3: =(E3/B5)*100 -> 58.807018
A4: Passive Income | B4: ='CASHFLOW BUDGET 3'!B23 -> 0 | D4: Investment | E4: ='CASHFLOW BUDGET 3'!C28 -> 190000 | F4: =(E4/B5)*100 -> 20
A5: Total Income | B5: ='CASHFLOW BUDGET 3'!B25 -> 950000 | D5: Financing | E5: ='CASHFLOW BUDGET 3'!C33 -> 0 | F5: =(E5/B5)*100 -> 0
